INFO:     Will watch for changes in these directories: ['/Users/MAC/chrome/bank-statement-converter-unified/backend']
INFO:     Uvicorn running on http://127.0.0.1:5000 (Press CTRL+C to quit)
INFO:     Started reloader process [14447] using WatchFiles
INFO:     Started server process [14450]
INFO:     Waiting for application startup.
INFO:     Application startup complete.
JWT Config loaded with SECRET_KEY: your-secret-key-here... (first 20 chars)
Starting up...
INFO:     127.0.0.1:58973 - "GET /health HTTP/1.1" 200 OK
WARNING:  WatchFiles detected changes in 'api/stripe_payments.py'. Reloading...
INFO:     Shutting down
INFO:     Waiting for application shutdown.
INFO:     Application shutdown complete.
INFO:     Finished server process [14450]
Shutting down...
INFO:     Started server process [14564]
INFO:     Waiting for application startup.
INFO:     Application startup complete.
WARNING:  WatchFiles detected changes in 'api/stripe_payments.py'. Reloading...
INFO:     Shutting down
INFO:     Waiting for application shutdown.
INFO:     Application shutdown complete.
INFO:     Finished server process [14564]
JWT Config loaded with SECRET_KEY: your-secret-key-here... (first 20 chars)
Starting up...
Shutting down...
INFO:     Started server process [14613]
INFO:     Waiting for application startup.
INFO:     Application startup complete.
JWT Config loaded with SECRET_KEY: your-secret-key-here... (first 20 chars)
Starting up...
INFO:     127.0.0.1:59114 - "POST /api/convert HTTP/1.1" 500 Internal Server Error
ERROR:    Exception in ASGI application
Traceback (most recent call last):
  File "/opt/anaconda3/lib/python3.12/site-packages/sqlalchemy/orm/clsregistry.py", line 515, in _resolve_name
    rval = d[token]
           ~^^^^^^^
  File "/opt/anaconda3/lib/python3.12/site-packages/sqlalchemy/util/_collections.py", line 346, in __missing__
    self[key] = val = self.creator(key)
                      ^^^^^^^^^^^^^^^^^
  File "/opt/anaconda3/lib/python3.12/site-packages/sqlalchemy/orm/clsregistry.py", line 483, in _access_cls
    return self.fallback[key]
           ~~~~~~~~~~~~~^^^^^
KeyError: 'Session'

The above exception was the direct cause of the following exception:

Traceback (most recent call last):
  File "/opt/anaconda3/lib/python3.12/site-packages/uvicorn/protocols/http/httptools_impl.py", line 426, in run_asgi
    result = await app(  # type: ignore[func-returns-value]
             ^^^^^^^^^^^^^^^^^^^^^^^^^^^^^^^^^^^^^^^^^^^^^^
  File "/opt/anaconda3/lib/python3.12/site-packages/uvicorn/middleware/proxy_headers.py", line 84, in __call__
    return await self.app(scope, receive, send)
           ^^^^^^^^^^^^^^^^^^^^^^^^^^^^^^^^^^^^
  File "/opt/anaconda3/lib/python3.12/site-packages/fastapi/applications.py", line 1106, in __call__
    await super().__call__(scope, receive, send)
  File "/opt/anaconda3/lib/python3.12/site-packages/starlette/applications.py", line 122, in __call__
    await self.middleware_stack(scope, receive, send)
  File "/opt/anaconda3/lib/python3.12/site-packages/starlette/middleware/errors.py", line 184, in __call__
    raise exc
  File "/opt/anaconda3/lib/python3.12/site-packages/starlette/middleware/errors.py", line 162, in __call__
    await self.app(scope, receive, _send)
  File "/opt/anaconda3/lib/python3.12/site-packages/starlette/middleware/base.py", line 108, in __call__
    response = await self.dispatch_func(request, call_next)
               ^^^^^^^^^^^^^^^^^^^^^^^^^^^^^^^^^^^^^^^^^^^^
  File "/Users/MAC/chrome/bank-statement-converter-unified/backend/middleware/csrf_middleware.py", line 36, in dispatch
    return await call_next(request)
           ^^^^^^^^^^^^^^^^^^^^^^^^
  File "/opt/anaconda3/lib/python3.12/site-packages/starlette/middleware/base.py", line 84, in call_next
    raise app_exc
  File "/opt/anaconda3/lib/python3.12/site-packages/starlette/middleware/base.py", line 70, in coro
    await self.app(scope, receive_or_disconnect, send_no_error)
  File "/opt/anaconda3/lib/python3.12/site-packages/starlette/middleware/cors.py", line 83, in __call__
    await self.app(scope, receive, send)
  File "/opt/anaconda3/lib/python3.12/site-packages/starlette/middleware/exceptions.py", line 79, in __call__
    raise exc
  File "/opt/anaconda3/lib/python3.12/site-packages/starlette/middleware/exceptions.py", line 68, in __call__
    await self.app(scope, receive, sender)
  File "/opt/anaconda3/lib/python3.12/site-packages/fastapi/middleware/asyncexitstack.py", line 20, in __call__
    raise e
  File "/opt/anaconda3/lib/python3.12/site-packages/fastapi/middleware/asyncexitstack.py", line 17, in __call__
    await self.app(scope, receive, send)
  File "/opt/anaconda3/lib/python3.12/site-packages/starlette/routing.py", line 718, in __call__
    await route.handle(scope, receive, send)
  File "/opt/anaconda3/lib/python3.12/site-packages/starlette/routing.py", line 276, in handle
    await self.app(scope, receive, send)
  File "/opt/anaconda3/lib/python3.12/site-packages/starlette/routing.py", line 66, in app
    response = await func(request)
               ^^^^^^^^^^^^^^^^^^^
  File "/opt/anaconda3/lib/python3.12/site-packages/fastapi/routing.py", line 274, in app
    raw_response = await run_endpoint_function(
                   ^^^^^^^^^^^^^^^^^^^^^^^^^^^^
  File "/opt/anaconda3/lib/python3.12/site-packages/fastapi/routing.py", line 191, in run_endpoint_function
    return await dependant.call(**values)
           ^^^^^^^^^^^^^^^^^^^^^^^^^^^^^^
  File "/Users/MAC/chrome/bank-statement-converter-unified/backend/api/statements.py", line 184, in convert_statement
    tracking = GenerationTracking.get_or_create(
               ^^^^^^^^^^^^^^^^^^^^^^^^^^^^^^^^^
  File "/Users/MAC/chrome/bank-statement-converter-unified/backend/models/database.py", line 207, in get_or_create
    query = session.query(cls)
            ^^^^^^^^^^^^^^^^^^
  File "/opt/anaconda3/lib/python3.12/site-packages/sqlalchemy/orm/session.py", line 2912, in query
    return self._query_cls(entities, self, **kwargs)
           ^^^^^^^^^^^^^^^^^^^^^^^^^^^^^^^^^^^^^^^^^
  File "/opt/anaconda3/lib/python3.12/site-packages/sqlalchemy/orm/query.py", line 276, in __init__
    self._set_entities(entities)
  File "/opt/anaconda3/lib/python3.12/site-packages/sqlalchemy/orm/query.py", line 289, in _set_entities
    coercions.expect(
  File "/opt/anaconda3/lib/python3.12/site-packages/sqlalchemy/sql/coercions.py", line 406, in expect
    insp._post_inspect
  File "/opt/anaconda3/lib/python3.12/site-packages/sqlalchemy/util/langhelpers.py", line 1260, in __get__
    obj.__dict__[self.__name__] = result = self.fget(obj)
                                           ^^^^^^^^^^^^^^
  File "/opt/anaconda3/lib/python3.12/site-packages/sqlalchemy/orm/mapper.py", line 2707, in _post_inspect
    self._check_configure()
  File "/opt/anaconda3/lib/python3.12/site-packages/sqlalchemy/orm/mapper.py", line 2386, in _check_configure
    _configure_registries({self.registry}, cascade=True)
  File "/opt/anaconda3/lib/python3.12/site-packages/sqlalchemy/orm/mapper.py", line 4199, in _configure_registries
    _do_configure_registries(registries, cascade)
  File "/opt/anaconda3/lib/python3.12/site-packages/sqlalchemy/orm/mapper.py", line 4240, in _do_configure_registries
    mapper._post_configure_properties()
  File "/opt/anaconda3/lib/python3.12/site-packages/sqlalchemy/orm/mapper.py", line 2403, in _post_configure_properties
    prop.init()
  File "/opt/anaconda3/lib/python3.12/site-packages/sqlalchemy/orm/interfaces.py", line 579, in init
    self.do_init()
  File "/opt/anaconda3/lib/python3.12/site-packages/sqlalchemy/orm/relationships.py", line 1635, in do_init
    self._setup_entity()
  File "/opt/anaconda3/lib/python3.12/site-packages/sqlalchemy/orm/relationships.py", line 1852, in _setup_entity
    self._clsregistry_resolve_name(argument)(),
    ^^^^^^^^^^^^^^^^^^^^^^^^^^^^^^^^^^^^^^^^^^
  File "/opt/anaconda3/lib/python3.12/site-packages/sqlalchemy/orm/clsregistry.py", line 519, in _resolve_name
    self._raise_for_name(name, err)
  File "/opt/anaconda3/lib/python3.12/site-packages/sqlalchemy/orm/clsregistry.py", line 500, in _raise_for_name
    raise exc.InvalidRequestError(
sqlalchemy.exc.InvalidRequestError: When initializing mapper Mapper[User(users)], expression 'Session' failed to locate a name ('Session'). If this is a class name, consider adding this relationship() to the <class 'models.database.User'> class after both dependent classes have been defined.
WARNING:  WatchFiles detected changes in 'api/stripe_payments.py'. Reloading...
INFO:     Shutting down
INFO:     Waiting for application shutdown.
INFO:     Application shutdown complete.
INFO:     Finished server process [14613]
Shutting down...
INFO:     Started server process [14667]
INFO:     Waiting for application startup.
INFO:     Application startup complete.
WARNING:  WatchFiles detected changes in 'api/stripe_payments.py'. Reloading...
INFO:     Shutting down
INFO:     Waiting for application shutdown.
INFO:     Application shutdown complete.
INFO:     Finished server process [14667]
JWT Config loaded with SECRET_KEY: your-secret-key-here... (first 20 chars)
Starting up...
Shutting down...
INFO:     Started server process [14716]
INFO:     Waiting for application startup.
INFO:     Application startup complete.
JWT Config loaded with SECRET_KEY: your-secret-key-here... (first 20 chars)
Starting up...
INFO:     127.0.0.1:59362 - "GET /v2/api/auth/csrf HTTP/1.1" 200 OK
INFO:     Shutting down
INFO:     Waiting for application shutdown.
INFO:     Application shutdown complete.
INFO:     Finished server process [14716]
Shutting down...
INFO:     Stopping reloader process [14447]
